Workbook

Sheet Beobachtung 26
A1: Produkt | B1: Berater*in | C1: Titel der Stelle | D1: Arbeitgeber / Institution | E1: Ort | F1: Bundesland / Land | G1: Ansprechperson (nach Möglichkeit Entscheider / kursiv = nach Recherche) | H1: Bewerbungsfrist | I1: Status | J1: Rückmeldung / Follow-Up | K1: Link zur Ausschreibung | L1: Institution zuletzt aufgenommen in Zeile: | M1: Score | N1: Relevant
C2: KW 3 ab 12.1.
B3: CK | C3: eine:n Referent:in (m/w/d) für den Förderkreis der Komischen Oper Berlin | D3: Komische Oper Berlin | G3: k.A. | H3: 18.1. | K3: https://oper-in-berlin.softgarden.io/job/61478307?l=de | L3: {=IFERROR(_xlfn.TEXTJOIN(", ", TRUE, IF(ISNUMBER(SEARCH(D3, D:D)), ROW(D:D), "")), "Kein Treffer")} -> 3, 146
B4: CK | C4: Kommunikationsmanager (m/w/d) | D4: Deutscher Tourismus Verband | G4: Norbert Kunz (Geschäftsführer) | H4: k.A. | I4: Mail und Magazin 23.01. | K4: https://www.deutschertourismusverband.de/fileadmin/user_upload/UEber_uns/Stellenangebote/DTV_Stellenanzeige_Kommunikationsmanager.pdf | L4: {=IFERROR(_xlfn.TEXTJOIN(", ", TRUE, IF(ISNUMBER(SEARCH(D4, D:D)), ROW(D:D), "")), "Kein Treffer")} -> 4
B5: CK | C5: Projektleitung Kulturwerkstatt | D5: DKB Stiftung | G5: Katrin Boerner | H5: k.A. | I5: Anruf und Mail 23.01. | J5: Haben auf die Berliner Ausschreibung 200! Bewerbungen bekommen. Ggf. besteht für LIEBENBERG Bedarf. | K5: https://www.dkb-stiftung.de/stiftung-jobs/ | L5: {=IFERROR(_xlfn.TEXTJOIN(", ", TRUE, IF(ISNUMBER(SEARCH(D5, D:D)), ROW(D:D), "")), "Kein Treffer")} -> 5
B6: DM | C6: Leitung der Bibliothek | D6: Gemeinde Gräfelfing | G6: Christina Zadaja | I6: 19.1. Postalisch | K6: https://www.mein-check-in.de/graefelfing/position-504054 | L6: {=IFERROR(_xlfn.TEXTJOIN(", ", TRUE, IF(ISNUMBER(SEARCH(D6, D:D)), ROW(D:D), "")), "Kein Treffer")} -> 6
A7: Nein | C7: Leiter*in Stabsstelle Kommunikation & Service / Pressesprecher*in (m/w/d) | D7: Kulturstiftung Dessau-Wörlitz | G7: Antje Unger | H7: 31.1. | K7: https://interamt.de/koop/app/stelle?0&id=1393498 | L7: {=IFERROR(_xlfn.TEXTJOIN(", ", TRUE, IF(ISNUMBER(SEARCH(D7, D:D)), ROW(D:D), "")), "Kein Treffer")} -> 7
C8: Museumsleitung (w/m/d) | D8: Stadt Bernau | G8: Mandy Freier | H8: 18.1. | K8: https://bernau-bei-berlin.ris-portal.de/web/guest/detail/-/stelle/detail/museumsleitung-w-m-d- | L8: {=IFERROR(_xlfn.TEXTJOIN(", ", TRUE, IF(ISNUMBER(SEARCH(D8, D:D)), ROW(D:D), "")), "Kein Treffer")} -> 8, 56
B9: CK | C9: Marketing Manager (m/w/d) | D9: Congress centrum Saar | G9: Elisabeth Fuchs | H9: 6.2. | I9: Anruf und Magazin Versand | J9: Haben gute Rückmeldung, aber benötigen ggf. Untersttzung für SalesPerson in 2 Monaten | K9: https://www.ccsaar.de/unternehmen/karriere/ | L9: {=IFERROR(_xlfn.TEXTJOIN(", ", TRUE, IF(ISNUMBER(SEARCH(D9, D:D)), ROW(D:D), "")), "Kein Treffer")} -> 9
B10: AME | C10: Projektleitung Eröffnung und Inbetriebnahme (m/w/d) | D10: Bauhaus Archiv / Museum für Gestaltung | G10: Tom Nehiba | H10: 8.2. | I10: KP versendet, ggf. Beauftragung für 2027 | K10: https://www.museumsbund.de/stellenangebote/projektleitung-eroeffnung-und-inbetriebnahme-m-w-d/ | L10: {=IFERROR(_xlfn.TEXTJOIN(", ", TRUE, IF(ISNUMBER(SEARCH(D10, D:D)), ROW(D:D), "")), "Kein Treffer")} -> 10
C11: Fachdienstleitung (m/w/d) | D11: Stadtverwaltung Neustadt an der Orla | G11: Fachdienstleiterin Verwaltung, Frau Jansen-Schleicher | H11: 13.2. | K11: https://www.arbeitsagentur.de/jobsuche/jobdetail/10001-1002371858-S | L11: {=IFERROR(_xlfn.TEXTJOIN(", ", TRUE, IF(ISNUMBER(SEARCH(D11, D:D)), ROW(D:D), "")), "Kein Treffer")} -> 11
B12: CK | C12: Kfm. Geschäftsführung Leitung Kommunikation | D12: Theater Lüneburg | G12: Personalabteilung | H12: 15.2. | I12: NSI Consulting beauftragt | K12: https://www.theater-lueneburg.de/service/stellenangebote | L12: {=IFERROR(_xlfn.TEXTJOIN(", ", TRUE, IF(ISNUMBER(SEARCH(D12, D:D)), ROW(D:D), "")), "Kein Treffer")} -> 12
C13: Dramaturg/in für Theater- und Familienprogramm (m/w/d) (Programmleitung) | D13: Monheimer Kulturwerke | G13: Britta Kisters | H13: K.A. | K13: https://www.monheimer-kulturwerke.de/de/stellenangebote/dramaturgin-theater-familienprogramm | L13: {=IFERROR(_xlfn.TEXTJOIN(", ", TRUE, IF(ISNUMBER(SEARCH(D13, D:D)), ROW(D:D), "")), "Kein Treffer")} -> 13
B14: AME | C14: Verlagsleitung | D14: Texte zur Kunst (berlin) | G14: Silvia Koch | H14: k.A. | I14: Austausch erfolgt | K14: https://arthist.net/archive/51419 | L14: {=IFERROR(_xlfn.TEXTJOIN(", ", TRUE, IF(ISNUMBER(SEARCH(D14, D:D)), ROW(D:D), "")), "Kein Treffer")} -> 14
B15: CK | C15: Direktor Finanzen Controlling | D15: Amadeu Antonio Stiftung Berlin | G15: (Vorstand) | H15: 46054 | I15: noch keinen erreicht | K15: https://www.stiftungen.org/jobs/stellenanzeige/director-finanzen-und-controlling-15714.html | L15: {=IFERROR(_xlfn.TEXTJOIN(", ", TRUE, IF(ISNUMBER(SEARCH(D15, D:D)), ROW(D:D), "")), "Kein Treffer")} -> 15
C16: Stiftungsvorstand | D16: Ilse Blank-Mezger-Hesselberger-Stiftung München (neu: seit 2/2023) /Förderung von Kunst u dt.-jüd. Geschichte | G16: Markus Kaum | H16: 46040 | K16: https://www.stiftungen.org/jobs/stellenanzeige/stiftungsvorstand-w-m-d-15706.html | L16: {=IFERROR(_xlfn.TEXTJOIN(", ", TRUE, IF(ISNUMBER(SEARCH(D16, D:D)), ROW(D:D), "")), "Kein Treffer")} -> 16
B17: CK | C17: Controller (in HH) | D17: Joachim Herz Stiftung | G17: Kerstin Krüger | H17: k.A. | L17: {=IFERROR(_xlfn.TEXTJOIN(", ", TRUE, IF(ISNUMBER(SEARCH(D17, D:D)), ROW(D:D), "")), "Kein Treffer")} -> 17
A18: KP | B18: CJ | C18: Direktion Stadtgeschichtliches Museum | D18: Stadt Duisburg | G18: Rachid Andich | H18: 46052 | I18: Telefonat am 12.01. | J18: Im Februar nachhaken | K18: https://karriere.duisburg.de/jobposting/3e33272ca864148a7c6f02f48f694631787b9ab80 | L18: {=IFERROR(_xlfn.TEXTJOIN(", ", TRUE, IF(ISNUMBER(SEARCH(D18, D:D)), ROW(D:D), "")), "Kein Treffer")} -> 18
B19: CK | C19: Direktorin / Direktor | D19: Stiftung Flucht, Vertreibung, Versöhnung Berlin | G19: Frau Unterabteilungsleiterin Korff | H19: 46040 | I19: BIn Mit Frau Bavendamm bereits in Abstimmung, Angebot versendet an BMI | K19: https://www.museumsbund.de/stellenangebote/direktorin-direktor/ | L19: {=IFERROR(_xlfn.TEXTJOIN(", ", TRUE, IF(ISNUMBER(SEARCH(D19, D:D)), ROW(D:D), "")), "Kein Treffer")} -> 19
C20: Referatsleiter*in (m/w/d) für das Referat „Kultur, Sport und Industriekultur“. | D20: Regionalverband Ruhr ; +49 201 2069-579 | G20: Frauke Heßberg | H20: 46051 | K20: https://www.rvr.ruhr/politik-regionalverband/ueber-uns/startseite-karriere/ | L20: {=IFERROR(_xlfn.TEXTJOIN(", ", TRUE, IF(ISNUMBER(SEARCH(D20, D:D)), ROW(D:D), "")), "Kein Treffer")} -> 20
B21: DM | C21: Verwaltungsdirektion | D21: Staatstheater Braunschweig | G21: Land Niedersachsen Personalreferat | H21: 22.1. | I21: Dran | K21: https://karriere.niedersachsen.de/stellenausschreibungen/verwaltungsdirektion-staatstheater-braunschweig-114057.html | L21: {=IFERROR(_xlfn.TEXTJOIN(", ", TRUE, IF(ISNUMBER(SEARCH(D21, D:D)), ROW(D:D), "")), "Kein Treffer")} -> 21
A22: KEX | B22: CJ | C22: Museumsleitung (m/w/d) | D22: Museum im Zeughaus Vechta | G22: Hr. Thomann | H22: 01.02. | I22: 15.1. | J22: 22.1. erl., ch, | K22: https://logahr1.kdo.de/bewerber-web/?companyEid=05600&tenant=05600&lang=D#position,id=12675e30-1f99-4a09-b0ef-9fff93ff5b09 | L22: {=IFERROR(_xlfn.TEXTJOIN(", ", TRUE, IF(ISNUMBER(SEARCH(D22, D:D)), ROW(D:D), "")), "Kein Treffer")} -> 22
B23: MR | C23: Geschäftsführung | D23: Leondinger Veranstaltungsmanagement | G23: Simone Lindinger | H23: 46022 | I23: 15.1. | L23: {=IFERROR(_xlfn.TEXTJOIN(", ", TRUE, IF(ISNUMBER(SEARCH(D23, D:D)), ROW(D:D), "")), "Kein Treffer")} -> 23
C24: KW 4 ab 20.1.
B25: FF | C25: Künstl. Leitung (ab 2027) | D25: Podium Esslingen | G25: Brigitte Russ-Scherer | H25: 46056 | K25: https://podium-esslingen.de/news/wir-suchen-nachfolge-kunstlerische-leitung-fur-2027-2026-01-09 | L25: {=IFERROR(_xlfn.TEXTJOIN(", ", TRUE, IF(ISNUMBER(SEARCH(D25, D:D)), ROW(D:D), "")), "Kein Treffer")} -> 25
B26: DM | C26: Direktor:in Marketing, Kommunikation und Besucherservice (m/w/d) | D26: Theater Chemnitz | G26: K.A. | H26: 46068 | I26: Rückmeldung erhalten, Follow-Up folgt | K26: https://www.theater-chemnitz.de/service/stellenangebote | L26: {=IFERROR(_xlfn.TEXTJOIN(", ", TRUE, IF(ISNUMBER(SEARCH(D26, D:D)), ROW(D:D), "")), "Kein Treffer")} -> 26
C27: Projektmanager:in IT-Services (w/m/d) für Berlins Kulturszene | D27: Technologie Stiftung Berlin | G27: Annette Kleffel (Leitung Abteilung Kultur & Bildung) | H27: 46050 | K27: https://technologiestiftung-berlin.jobs.personio.de/job/2490040?language=de%3Flanguage%3D&display=de | L27: {=IFERROR(_xlfn.TEXTJOIN(", ", TRUE, IF(ISNUMBER(SEARCH(D27, D:D)), ROW(D:D), "")), "Kein Treffer")} -> 27
A28: KP | B28: CJ | C28: Teamleiter:in für Verwaltung, Betrieb, Sicherheit (w/m/d) (39 WoSt) | D28: Jüdisches Museum Franken | G28: Daniela F. Eisenstein (Direktorin) | H28: 46056 | J28: kein Bedarf, CJ | K28: https://www.kultweet.de/jobs/JMF_Verwaltung.pdf | L28: {=IFERROR(_xlfn.TEXTJOIN(", ", TRUE, IF(ISNUMBER(SEARCH(D28, D:D)), ROW(D:D), "")), "Kein Treffer")} -> 28
B29: CK | C29: Leitung der Stabsstelle Stadtmarketing und Geschäftsführung der WIR VS GmbH (m/w/d) Citymanager | D29: Stadt Villingen-Schwenningen | G29: OB Jürgen Roth pers. Referent Tobias Herrmann | H29: 31.01.2026 15.02.2026 | K29: https://wir-vs.de/karriere/leitung-abteilung-tourismus-und-freizeit-2/ https://wir-vs.de/karriere/projektmanager-m-w-d-im-veranstaltungsmanagement-2/ | L29: {=IFERROR(_xlfn.TEXTJOIN(", ", TRUE, IF(ISNUMBER(SEARCH(D29, D:D)), ROW(D:D), "")), "Kein Treffer")} -> 29
A30: KEX | B30: CJ | C30: Fachbereichsleitung Museum / Bezirksgeschichtsarbeit (m/w/d) | D30: Bezirksamt Pankow von Berlin | G30: Fr. Lathan | H30: 46054 | I30: An Hr. Roter, Leiter Museum E-Mail am 28.1., ch | K30: https://www.karriereportal-stellen.berlin.de/Fachbereichsleitung-Museum-Bezirksgeschichtsarbeit-mwd-de-j63919.html | L30: {=IFERROR(_xlfn.TEXTJOIN(", ", TRUE, IF(ISNUMBER(SEARCH(D30, D:D)), ROW(D:D), "")), "Kein Treffer")} -> 30
C31: Projektmanager (w/m/d) für Veranstaltungen | D31: Deutsches Museum | G31: K.A. | H31: 46057 | K31: https://www.deutsches-museum.de/museum/ueber-uns/karriere/stellenangebote#c41809 | L31: {=IFERROR(_xlfn.TEXTJOIN(", ", TRUE, IF(ISNUMBER(SEARCH(D31, D:D)), ROW(D:D), "")), "Kein Treffer")} -> 31
C32: Technische Leitung im Theaterbetrieb (m/w/d) | D32: Semmel Concerts Entertainment GmbH | G32: k.A. | H32: k.A. ab sofort gesucht | K32: https://bdkv.de/wp-content/uploads/2025/12/SC_TL_Oberhausen_1225_bdkv.pdf | L32: {=IFERROR(_xlfn.TEXTJOIN(", ", TRUE, IF(ISNUMBER(SEARCH(D32, D:D)), ROW(D:D), "")), "Kein Treffer")} -> 32
B33: CK | C33: Leitung Tourismus und Kultur (m/w/d) | D33: Stadt Bad Doberan | G33: j.hahn@stadt-dbr.de | H33: 46053 | L33: {=IFERROR(_xlfn.TEXTJOIN(", ", TRUE, IF(ISNUMBER(SEARCH(D33, D:D)), ROW(D:D), "")), "Kein Treffer")} -> 33
B34: JK | C34: Museumsleitung (w/m/d) | D34: LWL-Museum Henrichshütte in Hattingen | G34: LWL-Museen für Industriekultur, Dr. Kirsten Baumann 0231 6961-136 | H34: 46059 | L34: {=IFERROR(_xlfn.TEXTJOIN(", ", TRUE, IF(ISNUMBER(SEARCH(D34, D:D)), ROW(D:D), "")), "Kein Treffer")} -> 34
B35: CK | C35: Direktorin / Direktor (w/m/d) der Gottfried Wilhelm Leibniz Bibliothek - Niedersächsische Landesbibliothek | D35: Ministerium Niedersachen | G35: Personalreferat (Tel. 0511/120-2438 | H35: 46042 | L35: {=IFERROR(_xlfn.TEXTJOIN(", ", TRUE, IF(ISNUMBER(SEARCH(D35, D:D)), ROW(D:D), "")), "Kein Treffer")} -> 35
B36: CK | C36: Stv. Leitung Controlling | D36: Stifterverband Essen | G36: Marion Langenbach | H36: keine | K36: https://www.stiftungen.org/jobs/stellenanzeige/stellvertretende-leitung-controlling-m-w-d-15761.html | L36: {=IFERROR(_xlfn.TEXTJOIN(", ", TRUE, IF(ISNUMBER(SEARCH(D36, D:D)), ROW(D:D), "")), "Kein Treffer")} -> 36
B37: CK | C37: PR & Communication Manager*in (m/w/d) in Vollzeit ... | D37: Stiftung Lesen | G37: Daniel Henzel | H37: 46053 | K37: https://jobs.kom.de/suche?keyword=&location=&homeoffice=&job=%26job%3Dpr-communication-managerin-mwd-in-vollzeit-40h-mainz-stiftung-lesen-12974281 | L37: {=IFERROR(_xlfn.TEXTJOIN(", ", TRUE, IF(ISNUMBER(SEARCH(D37, D:D)), ROW(D:D), "")), "Kein Treffer")} -> 37
A38: Nein | B38: MR | C38: Leitung Socia Media + Restaurator+Rechnungswesen (3 Stellen) | D38: Mumok | G38: Danijel Woynar | H38: 46062 | I38: 46043 | J38: haben jemanden gefunden | L38: {=IFERROR(_xlfn.TEXTJOIN(", ", TRUE, IF(ISNUMBER(SEARCH(D38, D:D)), ROW(D:D), "")), "Kein Treffer")} -> 38
C39: KW 5 ab 26.1.
B40: MR | C40: Assistenz Development Sponsoring | D40: Komitee der Salzburger Festspiele | G40: Solveig Eckert, Leitng Personal Festspielfond | H40: 46053 | I40: 46048 | L40: {=IFERROR(_xlfn.TEXTJOIN(", ", TRUE, IF(ISNUMBER(SEARCH(D40, D:D)), ROW(D:D), "")), "Kein Treffer")} -> 40
...

Sheet Zuteilung Stellenbörsen
A1: Anzahl | B1: Quelle | C1: Schwerpunkt | D1: URL | E1: Berater*in | F1: Pilotstatus | G1: Abrufmethode
A2: 3 | B2: EVVC.org Job.Center | C2: Veranstaltungszentren | D2: https://www.evvc.org/jobportal | E2: SBo | F2: nein | G2: HTTP
A3: 1 | B3: Kultweet | C3: Kultur, Bildung, Wissenschaft, Kommunikation | D3: https://www.kultweet.de/jobs.php | E3: DM | F3: ja | G3: HTTP
A4: 2 | B4: Open Biblio Jobs | C4: Bibliotheken, Archive | D4: https://bibliojobs.eu/ | E4: DM | F4: nein | G4: HTTP
A5: 1 | B5: Portal Kunstgeschichte | C5: Kunstgeschichte, Kulturwissenschaft | D5: https://portalkunstgeschichte.de/ | E5: AME | F5: nein
A6: 2 | B6: H-Soz-Kult | C6: Kulturwissenschaften, Kunstgeschichte, Geschichtswissenschaft | D6: https://www.hsozkult.de/job/page | E6: AME | F6: ja | G6: HTTP
A7: 3 | B7: H-ArtHist | C7: Kunstgeschichte, Bildende Kunst | D7: https://arthist.net/new.php?pn=mailing-list&mode=contribute | E7: AME | F7: nein
A8: 1 | B8: Bundesverband Museumspädagogik e.V. | C8: Museumspädagogik | D8: https://www.museumspaedagogik.org/aktuelles/jobs/ | E8: CJ | F8: nein
A9: 2 | B9: Deutscher Museumsbund e.V. | C9: Museum/Kunstverein | D9: https://www.museumsbund.de/stellenangebote/ | E9: CJ | F9: ja | G9: HTTP
A10: 3 | B10: BUND.de | C10: Verwaltung/Administration | D10: https://editor.bund.de | E10: CJ | F10: nein
A11: 4 | B11: Interamt | C11: Verwaltung/Administration | D11: https://interamt.de/cms/arbeitgeber.html | E11: CJ | F11: nein
A12: 1 | B12: nmz - neue musikzeitung | C12: Musik | D12: https://www.music-job.com | E12: WG | F12: nein
A13: 2 | B13: KOM Magazin für Kommunikation | C13: PR, Kommunikation, Medien | D13: https://stellenanzeigen.pressesprecher.com/stellenanzeige-schalten | E13: WG | F13: nein
A14: 3 | B14: stiftungen.org | C14: Stiftungen | D14: https://www.stiftungen.org/benutzerkonto.html | E14: WG | F14: nein
A15: 4 | B15: baito | C15: u.a Kulturstellen | D15: https://www.getbaito.com/de/jobs?job-branch=art-music-drama | E15: WG | F15: nein
A16: 1 | B16: KMM Netzwerk e.V. | C16: Kulturmanagement | E16: CK | F16: nein
A17: 2 | B17: bcsd e.V. | C17: City- und Stadtmarketing, Tourismus, Wirtschaftsförderung | D17: https://www.bcsd.de/service/jobboerse/ | E17: CK | F17: nein
A18: 3 | B18: destinet.de | C18: Tourismus und Destinationsmanagement | D18: https://www.destinet.de/stellenmarkt/stellenanzeigen-schalten | E18: CK | F18: nein
A19: 4 | B19: TourismusNews Deutschland | C19: Tourismus, Stadtmarketing | D19: https://jobs.tn-deutschland.com/order | E19: CK | F19: nein
A20: 5 | B20: PREGAS (außerdem Touristiklounge, EVENTFEX) | C20: Tourismus, Hotellerie, Gastronomie und MICE, Veranstaltungstätten | D20: https://pregas.de/stellenanzeige-schalten/ | E20: CK | F20: nein
A21: 1 | B21: Kultur Management Network | C21: Kulturmanagement | D21: https://www.kulturmanagement.net/Stellenmarkt-Eintrag | E21: JK | F21: nein
A22: 2 | B22: Kulturjobs.net | C22: Kultur - Österreich | D22: https://www.kulturjobs.net/eintrag.php | E22: JK | F22: nein
A23: 3 | B23: Frauen in Kultur & Medien (Deutscher Kulturrat) | C23: Kulturmanagement, Medien | D23: https://frauen-in-kultur-und-medien.de/aktuell/ausschreibungen/ | E23: JK | F23: nein
A24: 4 | B24: Gesines Jobtipps | C24: Bildung, Kultur & NGOs - Berlin, Leipzig, Halle | D24: https://gesinesjobtipps.de/freie-stelle-eintragen/ | E24: JK | F24: nein | G24: HTTP
A25: 1 | B25: Public Marketing | C25: Stadtmarketing, Marketing, Tourismus, Veranstaltungsstätten | D25: https://www.publicmarketing.eu/_rubric/index.php?rubric=Mediadaten | E25: LH | F25: nein
A26: 2 | B26: BDKV (Bundesverband der Konzert- und Veranstaltungswirtschaft e. V.) | C26: Veranstaltungszentren | D26: https://bdkv.de/jobboerse/jobangebote/ | E26: LH | F26: nein
A27: 1 | B27: buehnenjobs.de | C27: Theater/Orchester(-management), Musik | D27: https://www.buehnenverein.de/de/jobboerse | E27: LH | F27: nein | G27: HTTP
A28: 2 | B28: DTHG - Deutsche Theatertechnische Gesellschaft | C28: Bühnentechnik | D28: https://jobs.dthg.de/ | E28: LH | F28: nein | G28: HTTP
B29: KUPF Kulturplattform Stellenbörse | C29: Kultur - Österreich | D29: https://kupf.at/kulturjobs/ | E29: MR | F29: nein
B30: Institut für Kulturkonzepte Jobbörse | C30: Kultur - Österreich | D30: https://kulturkonzepte.at | E30: MR | F30: nein

Sheet Formeln
A1: Berater*innen | B1: Produkte | C1: Aktivitäten
A2: AM | B2: DP | C2: 4.1 Akquise Mail
A3: AME | B3: KP | C3: 4.2 Akquise Call
A4: CH | B4: KEX | C4: 4.3 Akquise Post
A5: CJ | B5: Nein | C5: 4.6 Versand Angebot
A6: CK | B6: KEX/Strat | C6: 4.7 Akquise Persönlich
A7: DM | B7: KIM | C7: 5 CRM Mail
A8: FF | C8: 5 CRM Call
A9: JK | C9: 5 CRM Post
A10: LH | C10: 5 CRM Treffen | I10: Zählenwenn | J10: =COUNTIF(F:F, "DP") -> 0
A11: MR | C11: 5.4 Versand Magazin
A12: OS | C12: 5.5 Versand Special
A13: SBo
A14: WG

Sheet Tabelle1
A1: Reaktionen auf Stellenbörsenbeobachtungen
A2: Berater*in | B2: AME | C2: CJ | D2: CK | E2: DM | F2: JK | G2: LH | H2: MR | I2: SBo | J2: WG
A3: Reaktionen | B3: =COUNTIF('Beobachtung 26'!B:B, "AME") -> 6 | C3: =COUNTIF('Beobachtung 26'!B:B, "CJ") -> 23 | D3: =COUNTIF('Beobachtung 26'!B:B, "CK") -> 31 | E3: =COUNTIF('Beobachtung 26'!B:B, "DM") -> 14 | F3: =COUNTIF('Beobachtung 26'!B:B, "JK") -> 3 | G3: =COUNTIF('Beobachtung 26'!B:B, "LH") -> 0 | H3: =COUNTIF('Beobachtung 26'!B:B, "MR") -> 9 | I3: =COUNTIF('Beobachtung 26'!B:B, "SBo") -> 1 | J3: =COUNTIF('Beobachtung 26'!B:B,"FF") -> 3
A5: Ansprache DP: | B5: =COUNTIF('Beobachtung 26'!A:A, "DP") -> 0 | C5: Ansprache KEX: | D5: =COUNTIF('Beobachtung 26'!A:A,"KEX") -> 2
A6: Ansprache KP: | B6: =COUNTIF('Beobachtung 26'!A:A, "KP") -> 7 | C6: Nein: | D6: =COUNTIF('Beobachtung 26'!A:A,"Nein") -> 7
A8: Stellenbörsenbeobachtung & Vertrieb KEX- Personal
A9: Erledigt | B9: Offen | C9: Hold
A12: Übersicht der Stellenbörsen, die KEX-Berater*innen beobachten - Stand 11.02.2025

Sheet Ausschreibungsfrequenz
A1: a | B1: b | C1: c
